Internal Server Error: /upload/
Traceback (most recent call last):
  File "D:\Programming\MediaUploadX\venv\Lib\site-packages\django\core\handlers\exception.py", line 55, in inner
    response = get_response(request)
               ^^^^^^^^^^^^^^^^^^^^^
  File "D:\Programming\MediaUploadX\venv\Lib\site-packages\django\core\handlers\base.py", line 197, in _get_response
    response = wrapped_callback(request, *callback_args, **callback_kwargs)
               ^^^^^^^^^^^^^^^^^^^^^^^^^^^^^^^^^^^^^^^^^^^^^^^^^^^^^^^^^^^^
  File "D:\Programming\MediaUploadX\files\views.py", line 293, in upload_media
    can_upload_exp = settings.CANNOT_ADD_MEDIA_MESSAGE
                     ^^^^^^^^^^^^^^^^^^^^^^^^^^^^^^^^^
  File "D:\Programming\MediaUploadX\venv\Lib\site-packages\django\conf\__init__.py", line 104, in __getattr__
    val = getattr(_wrapped, name)
          ^^^^^^^^^^^^^^^^^^^^^^^
AttributeError: 'Settings' object has no attribute 'CANNOT_ADD_MEDIA_MESSAGE'
"GET /upload/ HTTP/1.1" 500 86139
Internal Server Error: /accounts/signup/
Traceback (most recent call last):
  File "D:\Programming\MediaUploadX\venv\Lib\site-packages\kombu\utils\functional.py", line 32, in __call__
    return self.__value__
           ^^^^^^^^^^^^^^
AttributeError: 'ChannelPromise' object has no attribute '__value__'

During handling of the above exception, another exception occurred:

Traceback (most recent call last):
  File "D:\Programming\MediaUploadX\venv\Lib\site-packages\kombu\transport\virtual\base.py", line 951, in create_channel
    return self._avail_channels.pop()
           ^^^^^^^^^^^^^^^^^^^^^^^^^^
IndexError: pop from empty list

During handling of the above exception, another exception occurred:

Traceback (most recent call last):
  File "D:\Programming\MediaUploadX\venv\Lib\site-packages\redis\connection.py", line 707, in connect
    sock = self.retry.call_with_retry(
           ^^^^^^^^^^^^^^^^^^^^^^^^^^^
  File "D:\Programming\MediaUploadX\venv\Lib\site-packages\redis\retry.py", line 46, in call_with_retry
    return do()
           ^^^^
  File "D:\Programming\MediaUploadX\venv\Lib\site-packages\redis\connection.py", line 708, in <lambda>
    lambda: self._connect(), lambda error: self.disconnect(error)
            ^^^^^^^^^^^^^^^
  File "D:\Programming\MediaUploadX\venv\Lib\site-packages\redis\connection.py", line 1006, in _connect
    raise err
  File "D:\Programming\MediaUploadX\venv\Lib\site-packages\redis\connection.py", line 994, in _connect
    sock.connect(socket_address)
ConnectionRefusedError: [WinError 10061] No connection could be made because the target machine actively refused it

During handling of the above exception, another exception occurred:

Traceback (most recent call last):
  File "D:\Programming\MediaUploadX\venv\Lib\site-packages\kombu\connection.py", line 472, in _reraise_as_library_errors
    yield
  File "D:\Programming\MediaUploadX\venv\Lib\site-packages\kombu\connection.py", line 459, in _ensure_connection
    return retry_over_time(
           ^^^^^^^^^^^^^^^^
  File "D:\Programming\MediaUploadX\venv\Lib\site-packages\kombu\utils\functional.py", line 318, in retry_over_time
    return fun(*args, **kwargs)
           ^^^^^^^^^^^^^^^^^^^^
  File "D:\Programming\MediaUploadX\venv\Lib\site-packages\kombu\connection.py", line 941, in _connection_factory
    self._connection = self._establish_connection()
                       ^^^^^^^^^^^^^^^^^^^^^^^^^^^^
  File "D:\Programming\MediaUploadX\venv\Lib\site-packages\kombu\connection.py", line 867, in _establish_connection
    conn = self.transport.establish_connection()
           ^^^^^^^^^^^^^^^^^^^^^^^^^^^^^^^^^^^^^
  File "D:\Programming\MediaUploadX\venv\Lib\site-packages\kombu\transport\virtual\base.py", line 975, in establish_connection
    self._avail_channels.append(self.create_channel(self))
                                ^^^^^^^^^^^^^^^^^^^^^^^^^
  File "D:\Programming\MediaUploadX\venv\Lib\site-packages\kombu\transport\virtual\base.py", line 953, in create_channel
    channel = self.Channel(connection)
              ^^^^^^^^^^^^^^^^^^^^^^^^
  File "D:\Programming\MediaUploadX\venv\Lib\site-packages\kombu\transport\redis.py", line 741, in __init__
    self.client.ping()
  File "D:\Programming\MediaUploadX\venv\Lib\site-packages\redis\commands\core.py", line 1205, in ping
    return self.execute_command("PING", **kwargs)
           ^^^^^^^^^^^^^^^^^^^^^^^^^^^^^^^^^^^^^^
  File "D:\Programming\MediaUploadX\venv\Lib\site-packages\redis\client.py", line 1266, in execute_command
    conn = self.connection or pool.get_connection(command_name, **options)
                              ^^^^^^^^^^^^^^^^^^^^^^^^^^^^^^^^^^^^^^^^^^^^
  File "D:\Programming\MediaUploadX\venv\Lib\site-packages\redis\connection.py", line 1461, in get_connection
    connection.connect()
  File "D:\Programming\MediaUploadX\venv\Lib\site-packages\redis\connection.py", line 713, in connect
    raise ConnectionError(self._error_message(e))
redis.exceptions.ConnectionError: Error 10061 connecting to 127.0.0.1:6379. No connection could be made because the target machine actively refused it.

The above exception was the direct cause of the following exception:

Traceback (most recent call last):
  File "D:\Programming\MediaUploadX\venv\Lib\site-packages\django\core\handlers\exception.py", line 55, in inner
    response = get_response(request)
               ^^^^^^^^^^^^^^^^^^^^^
  File "D:\Programming\MediaUploadX\venv\Lib\site-packages\django\core\handlers\base.py", line 197, in _get_response
    response = wrapped_callback(request, *callback_args, **callback_kwargs)
               ^^^^^^^^^^^^^^^^^^^^^^^^^^^^^^^^^^^^^^^^^^^^^^^^^^^^^^^^^^^^
  File "D:\Programming\MediaUploadX\venv\Lib\site-packages\django\views\generic\base.py", line 104, in view
    return self.dispatch(request, *args, **kwargs)
           ^^^^^^^^^^^^^^^^^^^^^^^^^^^^^^^^^^^^^^^
  File "D:\Programming\MediaUploadX\venv\Lib\site-packages\django\utils\decorators.py", line 46, in _wrapper
    return bound_method(*args, **kwargs)
           ^^^^^^^^^^^^^^^^^^^^^^^^^^^^^
  File "D:\Programming\MediaUploadX\venv\Lib\site-packages\allauth\decorators.py", line 20, in wrap
    resp = function(request, *args, **kwargs)
           ^^^^^^^^^^^^^^^^^^^^^^^^^^^^^^^^^^
  File "D:\Programming\MediaUploadX\venv\Lib\site-packages\django\utils\decorators.py", line 46, in _wrapper
    return bound_method(*args, **kwargs)
           ^^^^^^^^^^^^^^^^^^^^^^^^^^^^^
  File "D:\Programming\MediaUploadX\venv\Lib\site-packages\django\views\decorators\debug.py", line 92, in sensitive_post_parameters_wrapper
    return view(request, *args, **kwargs)
           ^^^^^^^^^^^^^^^^^^^^^^^^^^^^^^
  File "D:\Programming\MediaUploadX\venv\Lib\site-packages\allauth\account\views.py", line 234, in dispatch
    return super(SignupView, self).dispatch(request, *args, **kwargs)
           ^^^^^^^^^^^^^^^^^^^^^^^^^^^^^^^^^^^^^^^^^^^^^^^^^^^^^^^^^^
  File "D:\Programming\MediaUploadX\venv\Lib\site-packages\allauth\account\views.py", line 77, in dispatch
    response = super(RedirectAuthenticatedUserMixin, self).dispatch(
               ^^^^^^^^^^^^^^^^^^^^^^^^^^^^^^^^^^^^^^^^^^^^^^^^^^^^^
  File "D:\Programming\MediaUploadX\venv\Lib\site-packages\allauth\account\views.py", line 207, in dispatch
    return super(CloseableSignupMixin, self).dispatch(request, *args, **kwargs)
           ^^^^^^^^^^^^^^^^^^^^^^^^^^^^^^^^^^^^^^^^^^^^^^^^^^^^^^^^^^^^^^^^^^^^
  File "D:\Programming\MediaUploadX\venv\Lib\site-packages\django\views\generic\base.py", line 143, in dispatch
    return handler(request, *args, **kwargs)
           ^^^^^^^^^^^^^^^^^^^^^^^^^^^^^^^^^
  File "D:\Programming\MediaUploadX\venv\Lib\site-packages\allauth\account\views.py", line 105, in post
    response = self.form_valid(form)
               ^^^^^^^^^^^^^^^^^^^^^
  File "D:\Programming\MediaUploadX\venv\Lib\site-packages\allauth\account\views.py", line 254, in form_valid
    return complete_signup(
           ^^^^^^^^^^^^^^^^
  File "D:\Programming\MediaUploadX\venv\Lib\site-packages\allauth\account\utils.py", line 186, in complete_signup
    return perform_login(
           ^^^^^^^^^^^^^^
  File "D:\Programming\MediaUploadX\venv\Lib\site-packages\allauth\account\utils.py", line 168, in perform_login
    response = adapter.pre_login(request, user, **hook_kwargs)
               ^^^^^^^^^^^^^^^^^^^^^^^^^^^^^^^^^^^^^^^^^^^^^^^
  File "D:\Programming\MediaUploadX\venv\Lib\site-packages\allauth\account\adapter.py", line 409, in pre_login
    send_email_confirmation(request, user, signup=signup, email=email)
  File "D:\Programming\MediaUploadX\venv\Lib\site-packages\allauth\account\utils.py", line 319, in send_email_confirmation
    email_address.send_confirmation(request, signup=signup)
  File "D:\Programming\MediaUploadX\venv\Lib\site-packages\allauth\account\models.py", line 60, in send_confirmation
    confirmation.send(request, signup=signup)
  File "D:\Programming\MediaUploadX\venv\Lib\site-packages\allauth\account\models.py", line 168, in send
    get_adapter(request).send_confirmation_mail(request, self, signup)
  File "D:\Programming\MediaUploadX\venv\Lib\site-packages\allauth\account\adapter.py", line 549, in send_confirmation_mail
    self.send_mail(email_template, emailconfirmation.email_address.email, ctx)
  File "D:\Programming\MediaUploadX\users\adapter.py", line 22, in send_mail
    msg.send(fail_silently=True)
  File "D:\Programming\MediaUploadX\venv\Lib\site-packages\django\core\mail\message.py", line 298, in send
    return self.get_connection(fail_silently).send_messages([self])
           ^^^^^^^^^^^^^^^^^^^^^^^^^^^^^^^^^^^^^^^^^^^^^^^^^^^^^^^^
  File "D:\Programming\MediaUploadX\venv\Lib\site-packages\djcelery_email\backends.py", line 17, in send_messages
    result_tasks.append(send_emails.delay(chunk_messages, self.init_kwargs))
                        ^^^^^^^^^^^^^^^^^^^^^^^^^^^^^^^^^^^^^^^^^^^^^^^^^^^
  File "D:\Programming\MediaUploadX\venv\Lib\site-packages\celery\app\task.py", line 444, in delay
    return self.apply_async(args, kwargs)
           ^^^^^^^^^^^^^^^^^^^^^^^^^^^^^^
  File "D:\Programming\MediaUploadX\venv\Lib\site-packages\celery\app\task.py", line 594, in apply_async
    return app.send_task(
           ^^^^^^^^^^^^^^
  File "D:\Programming\MediaUploadX\venv\Lib\site-packages\celery\app\base.py", line 798, in send_task
    amqp.send_task_message(P, name, message, **options)
  File "D:\Programming\MediaUploadX\venv\Lib\site-packages\celery\app\amqp.py", line 517, in send_task_message
    ret = producer.publish(
          ^^^^^^^^^^^^^^^^^
  File "D:\Programming\MediaUploadX\venv\Lib\site-packages\kombu\messaging.py", line 186, in publish
    return _publish(
           ^^^^^^^^^
  File "D:\Programming\MediaUploadX\venv\Lib\site-packages\kombu\connection.py", line 563, in _ensured
    return fun(*args, **kwargs)
           ^^^^^^^^^^^^^^^^^^^^
  File "D:\Programming\MediaUploadX\venv\Lib\site-packages\kombu\messaging.py", line 195, in _publish
    channel = self.channel
              ^^^^^^^^^^^^
  File "D:\Programming\MediaUploadX\venv\Lib\site-packages\kombu\messaging.py", line 218, in _get_channel
    channel = self._channel = channel()
                              ^^^^^^^^^
  File "D:\Programming\MediaUploadX\venv\Lib\site-packages\kombu\utils\functional.py", line 34, in __call__
    value = self.__value__ = self.__contract__()
                             ^^^^^^^^^^^^^^^^^^^
  File "D:\Programming\MediaUploadX\venv\Lib\site-packages\kombu\messaging.py", line 234, in <lambda>
    channel = ChannelPromise(lambda: connection.default_channel)
                                     ^^^^^^^^^^^^^^^^^^^^^^^^^^
  File "D:\Programming\MediaUploadX\venv\Lib\site-packages\kombu\connection.py", line 960, in default_channel
    self._ensure_connection(**conn_opts)
  File "D:\Programming\MediaUploadX\venv\Lib\site-packages\kombu\connection.py", line 458, in _ensure_connection
    with ctx():
  File "C:\Python\Lib\contextlib.py", line 155, in __exit__
    self.gen.throw(typ, value, traceback)
  File "D:\Programming\MediaUploadX\venv\Lib\site-packages\kombu\connection.py", line 476, in _reraise_as_library_errors
    raise ConnectionError(str(exc)) from exc
kombu.exceptions.OperationalError: Error 10061 connecting to 127.0.0.1:6379. No connection could be made because the target machine actively refused it.
"POST /accounts/signup/ HTTP/1.1" 500 369307
Internal Server Error: /admin/users/user/
Traceback (most recent call last):
  File "D:\Programming\MediaUploadX\venv\Lib\site-packages\django\db\backends\utils.py", line 89, in _execute
    return self.cursor.execute(sql, params)
           ^^^^^^^^^^^^^^^^^^^^^^^^^^^^^^^^
  File "D:\Programming\MediaUploadX\venv\Lib\site-packages\django\db\backends\sqlite3\base.py", line 328, in execute
    return super().execute(query, params)
           ^^^^^^^^^^^^^^^^^^^^^^^^^^^^^^
sqlite3.OperationalError: no such table: actions_mediaaction

The above exception was the direct cause of the following exception:

Traceback (most recent call last):
  File "D:\Programming\MediaUploadX\venv\Lib\site-packages\django\core\handlers\exception.py", line 55, in inner
    response = get_response(request)
               ^^^^^^^^^^^^^^^^^^^^^
  File "D:\Programming\MediaUploadX\venv\Lib\site-packages\django\core\handlers\base.py", line 197, in _get_response
    response = wrapped_callback(request, *callback_args, **callback_kwargs)
               ^^^^^^^^^^^^^^^^^^^^^^^^^^^^^^^^^^^^^^^^^^^^^^^^^^^^^^^^^^^^
  File "D:\Programming\MediaUploadX\venv\Lib\site-packages\django\contrib\admin\options.py", line 688, in wrapper
    return self.admin_site.admin_view(view)(*args, **kwargs)
           ^^^^^^^^^^^^^^^^^^^^^^^^^^^^^^^^^^^^^^^^^^^^^^^^^
  File "D:\Programming\MediaUploadX\venv\Lib\site-packages\django\utils\decorators.py", line 134, in _wrapper_view
    response = view_func(request, *args, **kwargs)
               ^^^^^^^^^^^^^^^^^^^^^^^^^^^^^^^^^^^
  File "D:\Programming\MediaUploadX\venv\Lib\site-packages\django\views\decorators\cache.py", line 62, in _wrapper_view_func
    response = view_func(request, *args, **kwargs)
               ^^^^^^^^^^^^^^^^^^^^^^^^^^^^^^^^^^^
  File "D:\Programming\MediaUploadX\venv\Lib\site-packages\django\contrib\admin\sites.py", line 242, in inner
    return view(request, *args, **kwargs)
           ^^^^^^^^^^^^^^^^^^^^^^^^^^^^^^
  File "D:\Programming\MediaUploadX\venv\Lib\site-packages\django\utils\decorators.py", line 46, in _wrapper
    return bound_method(*args, **kwargs)
           ^^^^^^^^^^^^^^^^^^^^^^^^^^^^^
  File "D:\Programming\MediaUploadX\venv\Lib\site-packages\django\utils\decorators.py", line 134, in _wrapper_view
    response = view_func(request, *args, **kwargs)
               ^^^^^^^^^^^^^^^^^^^^^^^^^^^^^^^^^^^
  File "D:\Programming\MediaUploadX\venv\Lib\site-packages\django\contrib\admin\options.py", line 1959, in changelist_view
    response = self.response_action(
               ^^^^^^^^^^^^^^^^^^^^^
  File "D:\Programming\MediaUploadX\venv\Lib\site-packages\django\contrib\admin\options.py", line 1593, in response_action
    response = func(self, request, queryset)
               ^^^^^^^^^^^^^^^^^^^^^^^^^^^^^
  File "D:\Programming\MediaUploadX\venv\Lib\site-packages\django\contrib\admin\actions.py", line 39, in delete_selected
    ) = modeladmin.get_deleted_objects(queryset, request)
        ^^^^^^^^^^^^^^^^^^^^^^^^^^^^^^^^^^^^^^^^^^^^^^^^^
  File "D:\Programming\MediaUploadX\venv\Lib\site-packages\django\contrib\admin\options.py", line 2101, in get_deleted_objects
    return get_deleted_objects(objs, request, self.admin_site)
           ^^^^^^^^^^^^^^^^^^^^^^^^^^^^^^^^^^^^^^^^^^^^^^^^^^^
  File "D:\Programming\MediaUploadX\venv\Lib\site-packages\django\contrib\admin\utils.py", line 121, in get_deleted_objects
    collector.collect(objs)
  File "D:\Programming\MediaUploadX\venv\Lib\site-packages\django\contrib\admin\utils.py", line 187, in collect
    return super().collect(objs, source_attr=source_attr, **kwargs)
           ^^^^^^^^^^^^^^^^^^^^^^^^^^^^^^^^^^^^^^^^^^^^^^^^^^^^^^^^
  File "D:\Programming\MediaUploadX\venv\Lib\site-packages\django\db\models\deletion.py", line 348, in collect
    if getattr(on_delete, "lazy_sub_objs", False) or sub_objs:
  File "D:\Programming\MediaUploadX\venv\Lib\site-packages\django\db\models\query.py", line 412, in __bool__
    self._fetch_all()
  File "D:\Programming\MediaUploadX\venv\Lib\site-packages\django\db\models\query.py", line 1881, in _fetch_all
    self._result_cache = list(self._iterable_class(self))
                         ^^^^^^^^^^^^^^^^^^^^^^^^^^^^^^^^
  File "D:\Programming\MediaUploadX\venv\Lib\site-packages\django\db\models\query.py", line 91, in __iter__
    results = compiler.execute_sql(
              ^^^^^^^^^^^^^^^^^^^^^
  File "D:\Programming\MediaUploadX\venv\Lib\site-packages\django\db\models\sql\compiler.py", line 1562, in execute_sql
    cursor.execute(sql, params)
  File "D:\Programming\MediaUploadX\venv\Lib\site-packages\django\db\backends\utils.py", line 102, in execute
    return super().execute(sql, params)
           ^^^^^^^^^^^^^^^^^^^^^^^^^^^^
  File "D:\Programming\MediaUploadX\venv\Lib\site-packages\django\db\backends\utils.py", line 67, in execute
    return self._execute_with_wrappers(
           ^^^^^^^^^^^^^^^^^^^^^^^^^^^^
  File "D:\Programming\MediaUploadX\venv\Lib\site-packages\django\db\backends\utils.py", line 80, in _execute_with_wrappers
    return executor(sql, params, many, context)
           ^^^^^^^^^^^^^^^^^^^^^^^^^^^^^^^^^^^^
  File "D:\Programming\MediaUploadX\venv\Lib\site-packages\django\db\backends\utils.py", line 84, in _execute
    with self.db.wrap_database_errors:
  File "D:\Programming\MediaUploadX\venv\Lib\site-packages\django\db\utils.py", line 91, in __exit__
    raise dj_exc_value.with_traceback(traceback) from exc_value
  File "D:\Programming\MediaUploadX\venv\Lib\site-packages\django\db\backends\utils.py", line 89, in _execute
    return self.cursor.execute(sql, params)
           ^^^^^^^^^^^^^^^^^^^^^^^^^^^^^^^^
  File "D:\Programming\MediaUploadX\venv\Lib\site-packages\django\db\backends\sqlite3\base.py", line 328, in execute
    return super().execute(query, params)
           ^^^^^^^^^^^^^^^^^^^^^^^^^^^^^^
django.db.utils.OperationalError: no such table: actions_mediaaction
"POST /admin/users/user/ HTTP/1.1" 500 221814
Internal Server Error: /admin/users/user/6/delete/
Traceback (most recent call last):
  File "D:\Programming\MediaUploadX\venv\Lib\site-packages\django\db\backends\utils.py", line 89, in _execute
    return self.cursor.execute(sql, params)
           ^^^^^^^^^^^^^^^^^^^^^^^^^^^^^^^^
  File "D:\Programming\MediaUploadX\venv\Lib\site-packages\django\db\backends\sqlite3\base.py", line 328, in execute
    return super().execute(query, params)
           ^^^^^^^^^^^^^^^^^^^^^^^^^^^^^^
sqlite3.OperationalError: no such table: actions_mediaaction

The above exception was the direct cause of the following exception:

Traceback (most recent call last):
  File "D:\Programming\MediaUploadX\venv\Lib\site-packages\django\core\handlers\exception.py", line 55, in inner
    response = get_response(request)
               ^^^^^^^^^^^^^^^^^^^^^
  File "D:\Programming\MediaUploadX\venv\Lib\site-packages\django\core\handlers\base.py", line 197, in _get_response
    response = wrapped_callback(request, *callback_args, **callback_kwargs)
               ^^^^^^^^^^^^^^^^^^^^^^^^^^^^^^^^^^^^^^^^^^^^^^^^^^^^^^^^^^^^
  File "D:\Programming\MediaUploadX\venv\Lib\site-packages\django\contrib\admin\options.py", line 688, in wrapper
    return self.admin_site.admin_view(view)(*args, **kwargs)
           ^^^^^^^^^^^^^^^^^^^^^^^^^^^^^^^^^^^^^^^^^^^^^^^^^
  File "D:\Programming\MediaUploadX\venv\Lib\site-packages\django\utils\decorators.py", line 134, in _wrapper_view
    response = view_func(request, *args, **kwargs)
               ^^^^^^^^^^^^^^^^^^^^^^^^^^^^^^^^^^^
  File "D:\Programming\MediaUploadX\venv\Lib\site-packages\django\views\decorators\cache.py", line 62, in _wrapper_view_func
    response = view_func(request, *args, **kwargs)
               ^^^^^^^^^^^^^^^^^^^^^^^^^^^^^^^^^^^
  File "D:\Programming\MediaUploadX\venv\Lib\site-packages\django\contrib\admin\sites.py", line 242, in inner
    return view(request, *args, **kwargs)
           ^^^^^^^^^^^^^^^^^^^^^^^^^^^^^^
  File "D:\Programming\MediaUploadX\venv\Lib\site-packages\django\utils\decorators.py", line 46, in _wrapper
    return bound_method(*args, **kwargs)
           ^^^^^^^^^^^^^^^^^^^^^^^^^^^^^
  File "D:\Programming\MediaUploadX\venv\Lib\site-packages\django\utils\decorators.py", line 134, in _wrapper_view
    response = view_func(request, *args, **kwargs)
               ^^^^^^^^^^^^^^^^^^^^^^^^^^^^^^^^^^^
  File "D:\Programming\MediaUploadX\venv\Lib\site-packages\django\contrib\admin\options.py", line 2106, in delete_view
    return self._delete_view(request, object_id, extra_context)
           ^^^^^^^^^^^^^^^^^^^^^^^^^^^^^^^^^^^^^^^^^^^^^^^^^^^^
  File "D:\Programming\MediaUploadX\venv\Lib\site-packages\django\contrib\admin\options.py", line 2133, in _delete_view
    ) = self.get_deleted_objects([obj], request)
        ^^^^^^^^^^^^^^^^^^^^^^^^^^^^^^^^^^^^^^^^
  File "D:\Programming\MediaUploadX\venv\Lib\site-packages\django\contrib\admin\options.py", line 2101, in get_deleted_objects
    return get_deleted_objects(objs, request, self.admin_site)
           ^^^^^^^^^^^^^^^^^^^^^^^^^^^^^^^^^^^^^^^^^^^^^^^^^^^
  File "D:\Programming\MediaUploadX\venv\Lib\site-packages\django\contrib\admin\utils.py", line 121, in get_deleted_objects
    collector.collect(objs)
  File "D:\Programming\MediaUploadX\venv\Lib\site-packages\django\contrib\admin\utils.py", line 187, in collect
    return super().collect(objs, source_attr=source_attr, **kwargs)
           ^^^^^^^^^^^^^^^^^^^^^^^^^^^^^^^^^^^^^^^^^^^^^^^^^^^^^^^^
  File "D:\Programming\MediaUploadX\venv\Lib\site-packages\django\db\models\deletion.py", line 348, in collect
    if getattr(on_delete, "lazy_sub_objs", False) or sub_objs:
  File "D:\Programming\MediaUploadX\venv\Lib\site-packages\django\db\models\query.py", line 412, in __bool__
    self._fetch_all()
  File "D:\Programming\MediaUploadX\venv\Lib\site-packages\django\db\models\query.py", line 1881, in _fetch_all
    self._result_cache = list(self._iterable_class(self))
                         ^^^^^^^^^^^^^^^^^^^^^^^^^^^^^^^^
  File "D:\Programming\MediaUploadX\venv\Lib\site-packages\django\db\models\query.py", line 91, in __iter__
    results = compiler.execute_sql(
              ^^^^^^^^^^^^^^^^^^^^^
  File "D:\Programming\MediaUploadX\venv\Lib\site-packages\django\db\models\sql\compiler.py", line 1562, in execute_sql
    cursor.execute(sql, params)
  File "D:\Programming\MediaUploadX\venv\Lib\site-packages\django\db\backends\utils.py", line 102, in execute
    return super().execute(sql, params)
           ^^^^^^^^^^^^^^^^^^^^^^^^^^^^
  File "D:\Programming\MediaUploadX\venv\Lib\site-packages\django\db\backends\utils.py", line 67, in execute
    return self._execute_with_wrappers(
           ^^^^^^^^^^^^^^^^^^^^^^^^^^^^
  File "D:\Programming\MediaUploadX\venv\Lib\site-packages\django\db\backends\utils.py", line 80, in _execute_with_wrappers
    return executor(sql, params, many, context)
           ^^^^^^^^^^^^^^^^^^^^^^^^^^^^^^^^^^^^
  File "D:\Programming\MediaUploadX\venv\Lib\site-packages\django\db\backends\utils.py", line 84, in _execute
    with self.db.wrap_database_errors:
  File "D:\Programming\MediaUploadX\venv\Lib\site-packages\django\db\utils.py", line 91, in __exit__
    raise dj_exc_value.with_traceback(traceback) from exc_value
  File "D:\Programming\MediaUploadX\venv\Lib\site-packages\django\db\backends\utils.py", line 89, in _execute
    return self.cursor.execute(sql, params)
           ^^^^^^^^^^^^^^^^^^^^^^^^^^^^^^^^
  File "D:\Programming\MediaUploadX\venv\Lib\site-packages\django\db\backends\sqlite3\base.py", line 328, in execute
    return super().execute(query, params)
           ^^^^^^^^^^^^^^^^^^^^^^^^^^^^^^
django.db.utils.OperationalError: no such table: actions_mediaaction
"GET /admin/users/user/6/delete/ HTTP/1.1" 500 214593
Internal Server Error: /api/v1/media
Traceback (most recent call last):
  File "D:\Programming\MediaUploadX\venv\Lib\site-packages\django_redis\cache.py", line 29, in _decorator
    return method(self, *args, **kwargs)
           ^^^^^^^^^^^^^^^^^^^^^^^^^^^^^
  File "D:\Programming\MediaUploadX\venv\Lib\site-packages\django_redis\cache.py", line 99, in _get
    return self.client.get(key, default=default, version=version, client=client)
           ^^^^^^^^^^^^^^^^^^^^^^^^^^^^^^^^^^^^^^^^^^^^^^^^^^^^^^^^^^^^^^^^^^^^^
  File "D:\Programming\MediaUploadX\venv\Lib\site-packages\django_redis\client\default.py", line 260, in get
    raise ConnectionInterrupted(connection=client) from e
django_redis.exceptions.ConnectionInterrupted: Redis ConnectionError: Error 10061 connecting to 127.0.0.1:6379. No connection could be made because the target machine actively refused it.

During handling of the above exception, another exception occurred:

Traceback (most recent call last):
  File "D:\Programming\MediaUploadX\venv\Lib\site-packages\django\core\handlers\exception.py", line 55, in inner
    response = get_response(request)
               ^^^^^^^^^^^^^^^^^^^^^
  File "D:\Programming\MediaUploadX\venv\Lib\site-packages\django\core\handlers\base.py", line 197, in _get_response
    response = wrapped_callback(request, *callback_args, **callback_kwargs)
               ^^^^^^^^^^^^^^^^^^^^^^^^^^^^^^^^^^^^^^^^^^^^^^^^^^^^^^^^^^^^
  File "D:\Programming\MediaUploadX\venv\Lib\site-packages\django\views\decorators\csrf.py", line 56, in wrapper_view
    return view_func(*args, **kwargs)
           ^^^^^^^^^^^^^^^^^^^^^^^^^^
  File "D:\Programming\MediaUploadX\venv\Lib\site-packages\django\views\generic\base.py", line 104, in view
    return self.dispatch(request, *args, **kwargs)
           ^^^^^^^^^^^^^^^^^^^^^^^^^^^^^^^^^^^^^^^
  File "D:\Programming\MediaUploadX\venv\Lib\site-packages\rest_framework\views.py", line 509, in dispatch
    response = self.handle_exception(exc)
               ^^^^^^^^^^^^^^^^^^^^^^^^^^
  File "D:\Programming\MediaUploadX\venv\Lib\site-packages\rest_framework\views.py", line 469, in handle_exception
    self.raise_uncaught_exception(exc)
  File "D:\Programming\MediaUploadX\venv\Lib\site-packages\rest_framework\views.py", line 480, in raise_uncaught_exception
    raise exc
  File "D:\Programming\MediaUploadX\venv\Lib\site-packages\rest_framework\views.py", line 506, in dispatch
    response = handler(request, *args, **kwargs)
               ^^^^^^^^^^^^^^^^^^^^^^^^^^^^^^^^^
  File "D:\Programming\MediaUploadX\files\api.py", line 99, in get
    media = show_recommended_media(request, limit=50)
            ^^^^^^^^^^^^^^^^^^^^^^^^^^^^^^^^^^^^^^^^^
  File "D:\Programming\MediaUploadX\files\methods.py", line 213, in show_recommended_media
    pmi = cache.get("popular_media_ids")
          ^^^^^^^^^^^^^^^^^^^^^^^^^^^^^^
  File "D:\Programming\MediaUploadX\venv\Lib\site-packages\django_redis\cache.py", line 92, in get
    value = self._get(key, default, version, client)
            ^^^^^^^^^^^^^^^^^^^^^^^^^^^^^^^^^^^^^^^^
  File "D:\Programming\MediaUploadX\venv\Lib\site-packages\django_redis\cache.py", line 36, in _decorator
    raise e.__cause__
  File "D:\Programming\MediaUploadX\venv\Lib\site-packages\django_redis\client\default.py", line 258, in get
    value = client.get(key)
            ^^^^^^^^^^^^^^^
  File "D:\Programming\MediaUploadX\venv\Lib\site-packages\redis\commands\core.py", line 1816, in get
    return self.execute_command("GET", name)
           ^^^^^^^^^^^^^^^^^^^^^^^^^^^^^^^^^
  File "D:\Programming\MediaUploadX\venv\Lib\site-packages\redis\client.py", line 1266, in execute_command
    conn = self.connection or pool.get_connection(command_name, **options)
                              ^^^^^^^^^^^^^^^^^^^^^^^^^^^^^^^^^^^^^^^^^^^^
  File "D:\Programming\MediaUploadX\venv\Lib\site-packages\redis\connection.py", line 1461, in get_connection
    connection.connect()
  File "D:\Programming\MediaUploadX\venv\Lib\site-packages\redis\connection.py", line 713, in connect
    raise ConnectionError(self._error_message(e))
redis.exceptions.ConnectionError: Error 10061 connecting to 127.0.0.1:6379. No connection could be made because the target machine actively refused it.
"GET /api/v1/media?show=recommended HTTP/1.1" 500 159943
