Internal Server Error: /accounts/signup/
Traceback (most recent call last):
  File "D:\Programming\MediaUploadX\venv\Lib\site-packages\django\core\handlers\exception.py", line 55, in inner
    response = get_response(request)
               ^^^^^^^^^^^^^^^^^^^^^
  File "D:\Programming\MediaUploadX\venv\Lib\site-packages\django\core\handlers\base.py", line 197, in _get_response
    response = wrapped_callback(request, *callback_args, **callback_kwargs)
               ^^^^^^^^^^^^^^^^^^^^^^^^^^^^^^^^^^^^^^^^^^^^^^^^^^^^^^^^^^^^
  File "D:\Programming\MediaUploadX\venv\Lib\site-packages\django\views\generic\base.py", line 104, in view
    return self.dispatch(request, *args, **kwargs)
           ^^^^^^^^^^^^^^^^^^^^^^^^^^^^^^^^^^^^^^^
  File "D:\Programming\MediaUploadX\venv\Lib\site-packages\django\utils\decorators.py", line 46, in _wrapper
    return bound_method(*args, **kwargs)
           ^^^^^^^^^^^^^^^^^^^^^^^^^^^^^
  File "D:\Programming\MediaUploadX\venv\Lib\site-packages\allauth\decorators.py", line 20, in wrap
    resp = function(request, *args, **kwargs)
           ^^^^^^^^^^^^^^^^^^^^^^^^^^^^^^^^^^
  File "D:\Programming\MediaUploadX\venv\Lib\site-packages\django\utils\decorators.py", line 46, in _wrapper
    return bound_method(*args, **kwargs)
           ^^^^^^^^^^^^^^^^^^^^^^^^^^^^^
  File "D:\Programming\MediaUploadX\venv\Lib\site-packages\django\views\decorators\debug.py", line 92, in sensitive_post_parameters_wrapper
    return view(request, *args, **kwargs)
           ^^^^^^^^^^^^^^^^^^^^^^^^^^^^^^
  File "D:\Programming\MediaUploadX\venv\Lib\site-packages\allauth\account\views.py", line 234, in dispatch
    return super(SignupView, self).dispatch(request, *args, **kwargs)
           ^^^^^^^^^^^^^^^^^^^^^^^^^^^^^^^^^^^^^^^^^^^^^^^^^^^^^^^^^^
  File "D:\Programming\MediaUploadX\venv\Lib\site-packages\allauth\account\views.py", line 77, in dispatch
    response = super(RedirectAuthenticatedUserMixin, self).dispatch(
               ^^^^^^^^^^^^^^^^^^^^^^^^^^^^^^^^^^^^^^^^^^^^^^^^^^^^^
  File "D:\Programming\MediaUploadX\venv\Lib\site-packages\allauth\account\views.py", line 207, in dispatch
    return super(CloseableSignupMixin, self).dispatch(request, *args, **kwargs)
           ^^^^^^^^^^^^^^^^^^^^^^^^^^^^^^^^^^^^^^^^^^^^^^^^^^^^^^^^^^^^^^^^^^^^
  File "D:\Programming\MediaUploadX\venv\Lib\site-packages\django\views\generic\base.py", line 143, in dispatch
    return handler(request, *args, **kwargs)
           ^^^^^^^^^^^^^^^^^^^^^^^^^^^^^^^^^
  File "D:\Programming\MediaUploadX\venv\Lib\site-packages\allauth\account\views.py", line 104, in post
    if form.is_valid():
       ^^^^^^^^^^^^^^^
  File "D:\Programming\MediaUploadX\venv\Lib\site-packages\django\forms\forms.py", line 201, in is_valid
    return self.is_bound and not self.errors
                                 ^^^^^^^^^^^
  File "D:\Programming\MediaUploadX\venv\Lib\site-packages\django\forms\forms.py", line 196, in errors
    self.full_clean()
  File "D:\Programming\MediaUploadX\venv\Lib\site-packages\django\forms\forms.py", line 433, in full_clean
    self._clean_fields()
  File "D:\Programming\MediaUploadX\venv\Lib\site-packages\django\forms\forms.py", line 448, in _clean_fields
    value = getattr(self, "clean_%s" % name)()
            ^^^^^^^^^^^^^^^^^^^^^^^^^^^^^^^^^^
  File "D:\Programming\MediaUploadX\venv\Lib\site-packages\allauth\account\forms.py", line 357, in clean_email
    value = get_adapter().clean_email(value)
            ^^^^^^^^^^^^^^^^^^^^^^^^^^^^^^^^
  File "D:\Programming\MediaUploadX\users\adapter.py", line 13, in clean_email
    if email.split("@")[1] in settings.RESTRICTED_DOMAINS_FOR_USER_REGISTRATION:
                              ^^^^^^^^^^^^^^^^^^^^^^^^^^^^^^^^^^^^^^^^^^^^^^^^^
  File "D:\Programming\MediaUploadX\venv\Lib\site-packages\django\conf\__init__.py", line 104, in __getattr__
    val = getattr(_wrapped, name)
          ^^^^^^^^^^^^^^^^^^^^^^^
AttributeError: 'Settings' object has no attribute 'RESTRICTED_DOMAINS_FOR_USER_REGISTRATION'
"POST /accounts/signup/ HTTP/1.1" 500 149059
Internal Server Error: /accounts/signup/
Traceback (most recent call last):
  File "D:\Programming\MediaUploadX\venv\Lib\site-packages\django\core\handlers\exception.py", line 55, in inner
    response = get_response(request)
               ^^^^^^^^^^^^^^^^^^^^^
  File "D:\Programming\MediaUploadX\venv\Lib\site-packages\django\core\handlers\base.py", line 197, in _get_response
    response = wrapped_callback(request, *callback_args, **callback_kwargs)
               ^^^^^^^^^^^^^^^^^^^^^^^^^^^^^^^^^^^^^^^^^^^^^^^^^^^^^^^^^^^^
  File "D:\Programming\MediaUploadX\venv\Lib\site-packages\django\views\generic\base.py", line 104, in view
    return self.dispatch(request, *args, **kwargs)
           ^^^^^^^^^^^^^^^^^^^^^^^^^^^^^^^^^^^^^^^
  File "D:\Programming\MediaUploadX\venv\Lib\site-packages\django\utils\decorators.py", line 46, in _wrapper
    return bound_method(*args, **kwargs)
           ^^^^^^^^^^^^^^^^^^^^^^^^^^^^^
  File "D:\Programming\MediaUploadX\venv\Lib\site-packages\allauth\decorators.py", line 20, in wrap
    resp = function(request, *args, **kwargs)
           ^^^^^^^^^^^^^^^^^^^^^^^^^^^^^^^^^^
  File "D:\Programming\MediaUploadX\venv\Lib\site-packages\django\utils\decorators.py", line 46, in _wrapper
    return bound_method(*args, **kwargs)
           ^^^^^^^^^^^^^^^^^^^^^^^^^^^^^
  File "D:\Programming\MediaUploadX\venv\Lib\site-packages\django\views\decorators\debug.py", line 92, in sensitive_post_parameters_wrapper
    return view(request, *args, **kwargs)
           ^^^^^^^^^^^^^^^^^^^^^^^^^^^^^^
  File "D:\Programming\MediaUploadX\venv\Lib\site-packages\allauth\account\views.py", line 234, in dispatch
    return super(SignupView, self).dispatch(request, *args, **kwargs)
           ^^^^^^^^^^^^^^^^^^^^^^^^^^^^^^^^^^^^^^^^^^^^^^^^^^^^^^^^^^
  File "D:\Programming\MediaUploadX\venv\Lib\site-packages\allauth\account\views.py", line 77, in dispatch
    response = super(RedirectAuthenticatedUserMixin, self).dispatch(
               ^^^^^^^^^^^^^^^^^^^^^^^^^^^^^^^^^^^^^^^^^^^^^^^^^^^^^
  File "D:\Programming\MediaUploadX\venv\Lib\site-packages\allauth\account\views.py", line 207, in dispatch
    return super(CloseableSignupMixin, self).dispatch(request, *args, **kwargs)
           ^^^^^^^^^^^^^^^^^^^^^^^^^^^^^^^^^^^^^^^^^^^^^^^^^^^^^^^^^^^^^^^^^^^^
  File "D:\Programming\MediaUploadX\venv\Lib\site-packages\django\views\generic\base.py", line 143, in dispatch
    return handler(request, *args, **kwargs)
           ^^^^^^^^^^^^^^^^^^^^^^^^^^^^^^^^^
  File "D:\Programming\MediaUploadX\venv\Lib\site-packages\allauth\account\views.py", line 104, in post
    if form.is_valid():
       ^^^^^^^^^^^^^^^
  File "D:\Programming\MediaUploadX\venv\Lib\site-packages\django\forms\forms.py", line 201, in is_valid
    return self.is_bound and not self.errors
                                 ^^^^^^^^^^^
  File "D:\Programming\MediaUploadX\venv\Lib\site-packages\django\forms\forms.py", line 196, in errors
    self.full_clean()
  File "D:\Programming\MediaUploadX\venv\Lib\site-packages\django\forms\forms.py", line 433, in full_clean
    self._clean_fields()
  File "D:\Programming\MediaUploadX\venv\Lib\site-packages\django\forms\forms.py", line 448, in _clean_fields
    value = getattr(self, "clean_%s" % name)()
            ^^^^^^^^^^^^^^^^^^^^^^^^^^^^^^^^^^
  File "D:\Programming\MediaUploadX\venv\Lib\site-packages\allauth\account\forms.py", line 357, in clean_email
    value = get_adapter().clean_email(value)
            ^^^^^^^^^^^^^^^^^^^^^^^^^^^^^^^^
  File "D:\Programming\MediaUploadX\users\adapter.py", line 13, in clean_email
    if email.split("@")[1] in settings.RESTRICTED_DOMAINS_FOR_USER_REGISTRATION:
                              ^^^^^^^^^^^^^^^^^^^^^^^^^^^^^^^^^^^^^^^^^^^^^^^^^
  File "D:\Programming\MediaUploadX\venv\Lib\site-packages\django\conf\__init__.py", line 104, in __getattr__
    val = getattr(_wrapped, name)
          ^^^^^^^^^^^^^^^^^^^^^^^
AttributeError: 'Settings' object has no attribute 'RESTRICTED_DOMAINS_FOR_USER_REGISTRATION'
"POST /accounts/signup/ HTTP/1.1" 500 149059
Internal Server Error: /accounts/signup/
Traceback (most recent call last):
  File "D:\Programming\MediaUploadX\venv\Lib\site-packages\django\core\handlers\exception.py", line 55, in inner
    response = get_response(request)
               ^^^^^^^^^^^^^^^^^^^^^
  File "D:\Programming\MediaUploadX\venv\Lib\site-packages\django\core\handlers\base.py", line 197, in _get_response
    response = wrapped_callback(request, *callback_args, **callback_kwargs)
               ^^^^^^^^^^^^^^^^^^^^^^^^^^^^^^^^^^^^^^^^^^^^^^^^^^^^^^^^^^^^
  File "D:\Programming\MediaUploadX\venv\Lib\site-packages\django\views\generic\base.py", line 104, in view
    return self.dispatch(request, *args, **kwargs)
           ^^^^^^^^^^^^^^^^^^^^^^^^^^^^^^^^^^^^^^^
  File "D:\Programming\MediaUploadX\venv\Lib\site-packages\django\utils\decorators.py", line 46, in _wrapper
    return bound_method(*args, **kwargs)
           ^^^^^^^^^^^^^^^^^^^^^^^^^^^^^
  File "D:\Programming\MediaUploadX\venv\Lib\site-packages\allauth\decorators.py", line 20, in wrap
    resp = function(request, *args, **kwargs)
           ^^^^^^^^^^^^^^^^^^^^^^^^^^^^^^^^^^
  File "D:\Programming\MediaUploadX\venv\Lib\site-packages\django\utils\decorators.py", line 46, in _wrapper
    return bound_method(*args, **kwargs)
           ^^^^^^^^^^^^^^^^^^^^^^^^^^^^^
  File "D:\Programming\MediaUploadX\venv\Lib\site-packages\django\views\decorators\debug.py", line 92, in sensitive_post_parameters_wrapper
    return view(request, *args, **kwargs)
           ^^^^^^^^^^^^^^^^^^^^^^^^^^^^^^
  File "D:\Programming\MediaUploadX\venv\Lib\site-packages\allauth\account\views.py", line 234, in dispatch
    return super(SignupView, self).dispatch(request, *args, **kwargs)
           ^^^^^^^^^^^^^^^^^^^^^^^^^^^^^^^^^^^^^^^^^^^^^^^^^^^^^^^^^^
  File "D:\Programming\MediaUploadX\venv\Lib\site-packages\allauth\account\views.py", line 77, in dispatch
    response = super(RedirectAuthenticatedUserMixin, self).dispatch(
               ^^^^^^^^^^^^^^^^^^^^^^^^^^^^^^^^^^^^^^^^^^^^^^^^^^^^^
  File "D:\Programming\MediaUploadX\venv\Lib\site-packages\allauth\account\views.py", line 207, in dispatch
    return super(CloseableSignupMixin, self).dispatch(request, *args, **kwargs)
           ^^^^^^^^^^^^^^^^^^^^^^^^^^^^^^^^^^^^^^^^^^^^^^^^^^^^^^^^^^^^^^^^^^^^
  File "D:\Programming\MediaUploadX\venv\Lib\site-packages\django\views\generic\base.py", line 143, in dispatch
    return handler(request, *args, **kwargs)
           ^^^^^^^^^^^^^^^^^^^^^^^^^^^^^^^^^
  File "D:\Programming\MediaUploadX\venv\Lib\site-packages\allauth\account\views.py", line 104, in post
    if form.is_valid():
       ^^^^^^^^^^^^^^^
  File "D:\Programming\MediaUploadX\venv\Lib\site-packages\django\forms\forms.py", line 201, in is_valid
    return self.is_bound and not self.errors
                                 ^^^^^^^^^^^
  File "D:\Programming\MediaUploadX\venv\Lib\site-packages\django\forms\forms.py", line 196, in errors
    self.full_clean()
  File "D:\Programming\MediaUploadX\venv\Lib\site-packages\django\forms\forms.py", line 433, in full_clean
    self._clean_fields()
  File "D:\Programming\MediaUploadX\venv\Lib\site-packages\django\forms\forms.py", line 448, in _clean_fields
    value = getattr(self, "clean_%s" % name)()
            ^^^^^^^^^^^^^^^^^^^^^^^^^^^^^^^^^^
  File "D:\Programming\MediaUploadX\venv\Lib\site-packages\allauth\account\forms.py", line 357, in clean_email
    value = get_adapter().clean_email(value)
            ^^^^^^^^^^^^^^^^^^^^^^^^^^^^^^^^
  File "D:\Programming\MediaUploadX\users\adapter.py", line 13, in clean_email
    if email.split("@")[1] in settings.RESTRICTED_DOMAINS_FOR_USER_REGISTRATION:
                              ^^^^^^^^^^^^^^^^^^^^^^^^^^^^^^^^^^^^^^^^^^^^^^^^^
  File "D:\Programming\MediaUploadX\venv\Lib\site-packages\django\conf\__init__.py", line 104, in __getattr__
    val = getattr(_wrapped, name)
          ^^^^^^^^^^^^^^^^^^^^^^^
AttributeError: 'Settings' object has no attribute 'RESTRICTED_DOMAINS_FOR_USER_REGISTRATION'
"POST /accounts/signup/ HTTP/1.1" 500 149059
Internal Server Error: /accounts/signup/
Traceback (most recent call last):
  File "D:\Programming\MediaUploadX\venv\Lib\site-packages\django\core\handlers\exception.py", line 55, in inner
    response = get_response(request)
               ^^^^^^^^^^^^^^^^^^^^^
  File "D:\Programming\MediaUploadX\venv\Lib\site-packages\django\core\handlers\base.py", line 197, in _get_response
    response = wrapped_callback(request, *callback_args, **callback_kwargs)
               ^^^^^^^^^^^^^^^^^^^^^^^^^^^^^^^^^^^^^^^^^^^^^^^^^^^^^^^^^^^^
  File "D:\Programming\MediaUploadX\venv\Lib\site-packages\django\views\generic\base.py", line 104, in view
    return self.dispatch(request, *args, **kwargs)
           ^^^^^^^^^^^^^^^^^^^^^^^^^^^^^^^^^^^^^^^
  File "D:\Programming\MediaUploadX\venv\Lib\site-packages\django\utils\decorators.py", line 46, in _wrapper
    return bound_method(*args, **kwargs)
           ^^^^^^^^^^^^^^^^^^^^^^^^^^^^^
  File "D:\Programming\MediaUploadX\venv\Lib\site-packages\allauth\decorators.py", line 20, in wrap
    resp = function(request, *args, **kwargs)
           ^^^^^^^^^^^^^^^^^^^^^^^^^^^^^^^^^^
  File "D:\Programming\MediaUploadX\venv\Lib\site-packages\django\utils\decorators.py", line 46, in _wrapper
    return bound_method(*args, **kwargs)
           ^^^^^^^^^^^^^^^^^^^^^^^^^^^^^
  File "D:\Programming\MediaUploadX\venv\Lib\site-packages\django\views\decorators\debug.py", line 92, in sensitive_post_parameters_wrapper
    return view(request, *args, **kwargs)
           ^^^^^^^^^^^^^^^^^^^^^^^^^^^^^^
  File "D:\Programming\MediaUploadX\venv\Lib\site-packages\allauth\account\views.py", line 234, in dispatch
    return super(SignupView, self).dispatch(request, *args, **kwargs)
           ^^^^^^^^^^^^^^^^^^^^^^^^^^^^^^^^^^^^^^^^^^^^^^^^^^^^^^^^^^
  File "D:\Programming\MediaUploadX\venv\Lib\site-packages\allauth\account\views.py", line 77, in dispatch
    response = super(RedirectAuthenticatedUserMixin, self).dispatch(
               ^^^^^^^^^^^^^^^^^^^^^^^^^^^^^^^^^^^^^^^^^^^^^^^^^^^^^
  File "D:\Programming\MediaUploadX\venv\Lib\site-packages\allauth\account\views.py", line 207, in dispatch
    return super(CloseableSignupMixin, self).dispatch(request, *args, **kwargs)
           ^^^^^^^^^^^^^^^^^^^^^^^^^^^^^^^^^^^^^^^^^^^^^^^^^^^^^^^^^^^^^^^^^^^^
  File "D:\Programming\MediaUploadX\venv\Lib\site-packages\django\views\generic\base.py", line 143, in dispatch
    return handler(request, *args, **kwargs)
           ^^^^^^^^^^^^^^^^^^^^^^^^^^^^^^^^^
  File "D:\Programming\MediaUploadX\venv\Lib\site-packages\allauth\account\views.py", line 104, in post
    if form.is_valid():
       ^^^^^^^^^^^^^^^
  File "D:\Programming\MediaUploadX\venv\Lib\site-packages\django\forms\forms.py", line 201, in is_valid
    return self.is_bound and not self.errors
                                 ^^^^^^^^^^^
  File "D:\Programming\MediaUploadX\venv\Lib\site-packages\django\forms\forms.py", line 196, in errors
    self.full_clean()
  File "D:\Programming\MediaUploadX\venv\Lib\site-packages\django\forms\forms.py", line 433, in full_clean
    self._clean_fields()
  File "D:\Programming\MediaUploadX\venv\Lib\site-packages\django\forms\forms.py", line 448, in _clean_fields
    value = getattr(self, "clean_%s" % name)()
            ^^^^^^^^^^^^^^^^^^^^^^^^^^^^^^^^^^
  File "D:\Programming\MediaUploadX\venv\Lib\site-packages\allauth\account\forms.py", line 348, in clean_username
    value = get_adapter().clean_username(value)
            ^^^^^^^^^^^^^^^^^^^^^^^^^^^^^^^^^^^
  File "D:\Programming\MediaUploadX\venv\Lib\site-packages\allauth\account\adapter.py", line 258, in clean_username
    for validator in app_settings.USERNAME_VALIDATORS:
                     ^^^^^^^^^^^^^^^^^^^^^^^^^^^^^^^^
  File "D:\Programming\MediaUploadX\venv\Lib\site-packages\allauth\account\app_settings.py", line 351, in USERNAME_VALIDATORS
    ret = import_attribute(path)
          ^^^^^^^^^^^^^^^^^^^^^^
  File "D:\Programming\MediaUploadX\venv\Lib\site-packages\allauth\utils.py", line 156, in import_attribute
    ret = getattr(importlib.import_module(pkg), attr)
                  ^^^^^^^^^^^^^^^^^^^^^^^^^^^^
  File "C:\Python\Lib\importlib\__init__.py", line 126, in import_module
    return _bootstrap._gcd_import(name[level:], package, level)
           ^^^^^^^^^^^^^^^^^^^^^^^^^^^^^^^^^^^^^^^^^^^^^^^^^^^^
  File "<frozen importlib._bootstrap>", line 1204, in _gcd_import
  File "<frozen importlib._bootstrap>", line 1176, in _find_and_load
  File "<frozen importlib._bootstrap>", line 1140, in _find_and_load_unlocked
ModuleNotFoundError: No module named 'users.validators'
"POST /accounts/signup/ HTTP/1.1" 500 163901
Internal Server Error: /accounts/signup/
Traceback (most recent call last):
  File "D:\Programming\MediaUploadX\venv\Lib\site-packages\kombu\utils\functional.py", line 32, in __call__
    return self.__value__
           ^^^^^^^^^^^^^^
AttributeError: 'ChannelPromise' object has no attribute '__value__'

During handling of the above exception, another exception occurred:

Traceback (most recent call last):
  File "D:\Programming\MediaUploadX\venv\Lib\site-packages\kombu\connection.py", line 472, in _reraise_as_library_errors
    yield
  File "D:\Programming\MediaUploadX\venv\Lib\site-packages\kombu\connection.py", line 459, in _ensure_connection
    return retry_over_time(
           ^^^^^^^^^^^^^^^^
  File "D:\Programming\MediaUploadX\venv\Lib\site-packages\kombu\utils\functional.py", line 318, in retry_over_time
    return fun(*args, **kwargs)
           ^^^^^^^^^^^^^^^^^^^^
  File "D:\Programming\MediaUploadX\venv\Lib\site-packages\kombu\connection.py", line 941, in _connection_factory
    self._connection = self._establish_connection()
                       ^^^^^^^^^^^^^^^^^^^^^^^^^^^^
  File "D:\Programming\MediaUploadX\venv\Lib\site-packages\kombu\connection.py", line 867, in _establish_connection
    conn = self.transport.establish_connection()
           ^^^^^^^^^^^^^^^^^^^^^^^^^^^^^^^^^^^^^
  File "D:\Programming\MediaUploadX\venv\Lib\site-packages\kombu\transport\pyamqp.py", line 203, in establish_connection
    conn.connect()
  File "D:\Programming\MediaUploadX\venv\Lib\site-packages\amqp\connection.py", line 323, in connect
    self.transport.connect()
  File "D:\Programming\MediaUploadX\venv\Lib\site-packages\amqp\transport.py", line 129, in connect
    self._connect(self.host, self.port, self.connect_timeout)
  File "D:\Programming\MediaUploadX\venv\Lib\site-packages\amqp\transport.py", line 184, in _connect
    self.sock.connect(sa)
ConnectionRefusedError: [WinError 10061] No connection could be made because the target machine actively refused it

The above exception was the direct cause of the following exception:

Traceback (most recent call last):
  File "D:\Programming\MediaUploadX\venv\Lib\site-packages\django\core\handlers\exception.py", line 55, in inner
    response = get_response(request)
               ^^^^^^^^^^^^^^^^^^^^^
  File "D:\Programming\MediaUploadX\venv\Lib\site-packages\django\core\handlers\base.py", line 197, in _get_response
    response = wrapped_callback(request, *callback_args, **callback_kwargs)
               ^^^^^^^^^^^^^^^^^^^^^^^^^^^^^^^^^^^^^^^^^^^^^^^^^^^^^^^^^^^^
  File "D:\Programming\MediaUploadX\venv\Lib\site-packages\django\views\generic\base.py", line 104, in view
    return self.dispatch(request, *args, **kwargs)
           ^^^^^^^^^^^^^^^^^^^^^^^^^^^^^^^^^^^^^^^
  File "D:\Programming\MediaUploadX\venv\Lib\site-packages\django\utils\decorators.py", line 46, in _wrapper
    return bound_method(*args, **kwargs)
           ^^^^^^^^^^^^^^^^^^^^^^^^^^^^^
  File "D:\Programming\MediaUploadX\venv\Lib\site-packages\allauth\decorators.py", line 20, in wrap
    resp = function(request, *args, **kwargs)
           ^^^^^^^^^^^^^^^^^^^^^^^^^^^^^^^^^^
  File "D:\Programming\MediaUploadX\venv\Lib\site-packages\django\utils\decorators.py", line 46, in _wrapper
    return bound_method(*args, **kwargs)
           ^^^^^^^^^^^^^^^^^^^^^^^^^^^^^
  File "D:\Programming\MediaUploadX\venv\Lib\site-packages\django\views\decorators\debug.py", line 92, in sensitive_post_parameters_wrapper
    return view(request, *args, **kwargs)
           ^^^^^^^^^^^^^^^^^^^^^^^^^^^^^^
  File "D:\Programming\MediaUploadX\venv\Lib\site-packages\allauth\account\views.py", line 234, in dispatch
    return super(SignupView, self).dispatch(request, *args, **kwargs)
           ^^^^^^^^^^^^^^^^^^^^^^^^^^^^^^^^^^^^^^^^^^^^^^^^^^^^^^^^^^
  File "D:\Programming\MediaUploadX\venv\Lib\site-packages\allauth\account\views.py", line 77, in dispatch
    response = super(RedirectAuthenticatedUserMixin, self).dispatch(
               ^^^^^^^^^^^^^^^^^^^^^^^^^^^^^^^^^^^^^^^^^^^^^^^^^^^^^
  File "D:\Programming\MediaUploadX\venv\Lib\site-packages\allauth\account\views.py", line 207, in dispatch
    return super(CloseableSignupMixin, self).dispatch(request, *args, **kwargs)
           ^^^^^^^^^^^^^^^^^^^^^^^^^^^^^^^^^^^^^^^^^^^^^^^^^^^^^^^^^^^^^^^^^^^^
  File "D:\Programming\MediaUploadX\venv\Lib\site-packages\django\views\generic\base.py", line 143, in dispatch
    return handler(request, *args, **kwargs)
           ^^^^^^^^^^^^^^^^^^^^^^^^^^^^^^^^^
  File "D:\Programming\MediaUploadX\venv\Lib\site-packages\allauth\account\views.py", line 105, in post
    response = self.form_valid(form)
               ^^^^^^^^^^^^^^^^^^^^^
  File "D:\Programming\MediaUploadX\venv\Lib\site-packages\allauth\account\views.py", line 254, in form_valid
    return complete_signup(
           ^^^^^^^^^^^^^^^^
  File "D:\Programming\MediaUploadX\venv\Lib\site-packages\allauth\account\utils.py", line 186, in complete_signup
    return perform_login(
           ^^^^^^^^^^^^^^
  File "D:\Programming\MediaUploadX\venv\Lib\site-packages\allauth\account\utils.py", line 168, in perform_login
    response = adapter.pre_login(request, user, **hook_kwargs)
               ^^^^^^^^^^^^^^^^^^^^^^^^^^^^^^^^^^^^^^^^^^^^^^^
  File "D:\Programming\MediaUploadX\venv\Lib\site-packages\allauth\account\adapter.py", line 409, in pre_login
    send_email_confirmation(request, user, signup=signup, email=email)
  File "D:\Programming\MediaUploadX\venv\Lib\site-packages\allauth\account\utils.py", line 319, in send_email_confirmation
    email_address.send_confirmation(request, signup=signup)
  File "D:\Programming\MediaUploadX\venv\Lib\site-packages\allauth\account\models.py", line 60, in send_confirmation
    confirmation.send(request, signup=signup)
  File "D:\Programming\MediaUploadX\venv\Lib\site-packages\allauth\account\models.py", line 168, in send
    get_adapter(request).send_confirmation_mail(request, self, signup)
  File "D:\Programming\MediaUploadX\venv\Lib\site-packages\allauth\account\adapter.py", line 549, in send_confirmation_mail
    self.send_mail(email_template, emailconfirmation.email_address.email, ctx)
  File "D:\Programming\MediaUploadX\users\adapter.py", line 22, in send_mail
    msg.send(fail_silently=True)
  File "D:\Programming\MediaUploadX\venv\Lib\site-packages\django\core\mail\message.py", line 298, in send
    return self.get_connection(fail_silently).send_messages([self])
           ^^^^^^^^^^^^^^^^^^^^^^^^^^^^^^^^^^^^^^^^^^^^^^^^^^^^^^^^
  File "D:\Programming\MediaUploadX\venv\Lib\site-packages\djcelery_email\backends.py", line 17, in send_messages
    result_tasks.append(send_emails.delay(chunk_messages, self.init_kwargs))
                        ^^^^^^^^^^^^^^^^^^^^^^^^^^^^^^^^^^^^^^^^^^^^^^^^^^^
  File "D:\Programming\MediaUploadX\venv\Lib\site-packages\celery\app\task.py", line 444, in delay
    return self.apply_async(args, kwargs)
           ^^^^^^^^^^^^^^^^^^^^^^^^^^^^^^
  File "D:\Programming\MediaUploadX\venv\Lib\site-packages\celery\app\task.py", line 594, in apply_async
    return app.send_task(
           ^^^^^^^^^^^^^^
  File "D:\Programming\MediaUploadX\venv\Lib\site-packages\celery\app\base.py", line 798, in send_task
    amqp.send_task_message(P, name, message, **options)
  File "D:\Programming\MediaUploadX\venv\Lib\site-packages\celery\app\amqp.py", line 517, in send_task_message
    ret = producer.publish(
          ^^^^^^^^^^^^^^^^^
  File "D:\Programming\MediaUploadX\venv\Lib\site-packages\kombu\messaging.py", line 186, in publish
    return _publish(
           ^^^^^^^^^
  File "D:\Programming\MediaUploadX\venv\Lib\site-packages\kombu\connection.py", line 563, in _ensured
    return fun(*args, **kwargs)
           ^^^^^^^^^^^^^^^^^^^^
  File "D:\Programming\MediaUploadX\venv\Lib\site-packages\kombu\messaging.py", line 195, in _publish
    channel = self.channel
              ^^^^^^^^^^^^
  File "D:\Programming\MediaUploadX\venv\Lib\site-packages\kombu\messaging.py", line 218, in _get_channel
    channel = self._channel = channel()
                              ^^^^^^^^^
  File "D:\Programming\MediaUploadX\venv\Lib\site-packages\kombu\utils\functional.py", line 34, in __call__
    value = self.__value__ = self.__contract__()
                             ^^^^^^^^^^^^^^^^^^^
  File "D:\Programming\MediaUploadX\venv\Lib\site-packages\kombu\messaging.py", line 234, in <lambda>
    channel = ChannelPromise(lambda: connection.default_channel)
                                     ^^^^^^^^^^^^^^^^^^^^^^^^^^
  File "D:\Programming\MediaUploadX\venv\Lib\site-packages\kombu\connection.py", line 960, in default_channel
    self._ensure_connection(**conn_opts)
  File "D:\Programming\MediaUploadX\venv\Lib\site-packages\kombu\connection.py", line 458, in _ensure_connection
    with ctx():
  File "C:\Python\Lib\contextlib.py", line 155, in __exit__
    self.gen.throw(typ, value, traceback)
  File "D:\Programming\MediaUploadX\venv\Lib\site-packages\kombu\connection.py", line 476, in _reraise_as_library_errors
    raise ConnectionError(str(exc)) from exc
kombu.exceptions.OperationalError: [WinError 10061] No connection could be made because the target machine actively refused it
"POST /accounts/signup/ HTTP/1.1" 500 325880
Internal Server Error: /accounts/signup/
Traceback (most recent call last):
  File "D:\Programming\MediaUploadX\venv\Lib\site-packages\kombu\utils\functional.py", line 32, in __call__
    return self.__value__
           ^^^^^^^^^^^^^^
AttributeError: 'ChannelPromise' object has no attribute '__value__'

During handling of the above exception, another exception occurred:

Traceback (most recent call last):
  File "D:\Programming\MediaUploadX\venv\Lib\site-packages\kombu\connection.py", line 472, in _reraise_as_library_errors
    yield
  File "D:\Programming\MediaUploadX\venv\Lib\site-packages\kombu\connection.py", line 459, in _ensure_connection
    return retry_over_time(
           ^^^^^^^^^^^^^^^^
  File "D:\Programming\MediaUploadX\venv\Lib\site-packages\kombu\utils\functional.py", line 318, in retry_over_time
    return fun(*args, **kwargs)
           ^^^^^^^^^^^^^^^^^^^^
  File "D:\Programming\MediaUploadX\venv\Lib\site-packages\kombu\connection.py", line 941, in _connection_factory
    self._connection = self._establish_connection()
                       ^^^^^^^^^^^^^^^^^^^^^^^^^^^^
  File "D:\Programming\MediaUploadX\venv\Lib\site-packages\kombu\connection.py", line 867, in _establish_connection
    conn = self.transport.establish_connection()
           ^^^^^^^^^^^^^^^^^^^^^^^^^^^^^^^^^^^^^
  File "D:\Programming\MediaUploadX\venv\Lib\site-packages\kombu\transport\pyamqp.py", line 203, in establish_connection
    conn.connect()
  File "D:\Programming\MediaUploadX\venv\Lib\site-packages\amqp\connection.py", line 323, in connect
    self.transport.connect()
  File "D:\Programming\MediaUploadX\venv\Lib\site-packages\amqp\transport.py", line 129, in connect
    self._connect(self.host, self.port, self.connect_timeout)
  File "D:\Programming\MediaUploadX\venv\Lib\site-packages\amqp\transport.py", line 184, in _connect
    self.sock.connect(sa)
ConnectionRefusedError: [WinError 10061] No connection could be made because the target machine actively refused it

The above exception was the direct cause of the following exception:

Traceback (most recent call last):
  File "D:\Programming\MediaUploadX\venv\Lib\site-packages\django\core\handlers\exception.py", line 55, in inner
    response = get_response(request)
               ^^^^^^^^^^^^^^^^^^^^^
  File "D:\Programming\MediaUploadX\venv\Lib\site-packages\django\core\handlers\base.py", line 197, in _get_response
    response = wrapped_callback(request, *callback_args, **callback_kwargs)
               ^^^^^^^^^^^^^^^^^^^^^^^^^^^^^^^^^^^^^^^^^^^^^^^^^^^^^^^^^^^^
  File "D:\Programming\MediaUploadX\venv\Lib\site-packages\django\views\generic\base.py", line 104, in view
    return self.dispatch(request, *args, **kwargs)
           ^^^^^^^^^^^^^^^^^^^^^^^^^^^^^^^^^^^^^^^
  File "D:\Programming\MediaUploadX\venv\Lib\site-packages\django\utils\decorators.py", line 46, in _wrapper
    return bound_method(*args, **kwargs)
           ^^^^^^^^^^^^^^^^^^^^^^^^^^^^^
  File "D:\Programming\MediaUploadX\venv\Lib\site-packages\allauth\decorators.py", line 20, in wrap
    resp = function(request, *args, **kwargs)
           ^^^^^^^^^^^^^^^^^^^^^^^^^^^^^^^^^^
  File "D:\Programming\MediaUploadX\venv\Lib\site-packages\django\utils\decorators.py", line 46, in _wrapper
    return bound_method(*args, **kwargs)
           ^^^^^^^^^^^^^^^^^^^^^^^^^^^^^
  File "D:\Programming\MediaUploadX\venv\Lib\site-packages\django\views\decorators\debug.py", line 92, in sensitive_post_parameters_wrapper
    return view(request, *args, **kwargs)
           ^^^^^^^^^^^^^^^^^^^^^^^^^^^^^^
  File "D:\Programming\MediaUploadX\venv\Lib\site-packages\allauth\account\views.py", line 234, in dispatch
    return super(SignupView, self).dispatch(request, *args, **kwargs)
           ^^^^^^^^^^^^^^^^^^^^^^^^^^^^^^^^^^^^^^^^^^^^^^^^^^^^^^^^^^
  File "D:\Programming\MediaUploadX\venv\Lib\site-packages\allauth\account\views.py", line 77, in dispatch
    response = super(RedirectAuthenticatedUserMixin, self).dispatch(
               ^^^^^^^^^^^^^^^^^^^^^^^^^^^^^^^^^^^^^^^^^^^^^^^^^^^^^
  File "D:\Programming\MediaUploadX\venv\Lib\site-packages\allauth\account\views.py", line 207, in dispatch
    return super(CloseableSignupMixin, self).dispatch(request, *args, **kwargs)
           ^^^^^^^^^^^^^^^^^^^^^^^^^^^^^^^^^^^^^^^^^^^^^^^^^^^^^^^^^^^^^^^^^^^^
  File "D:\Programming\MediaUploadX\venv\Lib\site-packages\django\views\generic\base.py", line 143, in dispatch
    return handler(request, *args, **kwargs)
           ^^^^^^^^^^^^^^^^^^^^^^^^^^^^^^^^^
  File "D:\Programming\MediaUploadX\venv\Lib\site-packages\allauth\account\views.py", line 105, in post
    response = self.form_valid(form)
               ^^^^^^^^^^^^^^^^^^^^^
  File "D:\Programming\MediaUploadX\venv\Lib\site-packages\allauth\account\views.py", line 254, in form_valid
    return complete_signup(
           ^^^^^^^^^^^^^^^^
  File "D:\Programming\MediaUploadX\venv\Lib\site-packages\allauth\account\utils.py", line 186, in complete_signup
    return perform_login(
           ^^^^^^^^^^^^^^
  File "D:\Programming\MediaUploadX\venv\Lib\site-packages\allauth\account\utils.py", line 168, in perform_login
    response = adapter.pre_login(request, user, **hook_kwargs)
               ^^^^^^^^^^^^^^^^^^^^^^^^^^^^^^^^^^^^^^^^^^^^^^^
  File "D:\Programming\MediaUploadX\venv\Lib\site-packages\allauth\account\adapter.py", line 409, in pre_login
    send_email_confirmation(request, user, signup=signup, email=email)
  File "D:\Programming\MediaUploadX\venv\Lib\site-packages\allauth\account\utils.py", line 319, in send_email_confirmation
    email_address.send_confirmation(request, signup=signup)
  File "D:\Programming\MediaUploadX\venv\Lib\site-packages\allauth\account\models.py", line 60, in send_confirmation
    confirmation.send(request, signup=signup)
  File "D:\Programming\MediaUploadX\venv\Lib\site-packages\allauth\account\models.py", line 168, in send
    get_adapter(request).send_confirmation_mail(request, self, signup)
  File "D:\Programming\MediaUploadX\venv\Lib\site-packages\allauth\account\adapter.py", line 549, in send_confirmation_mail
    self.send_mail(email_template, emailconfirmation.email_address.email, ctx)
  File "D:\Programming\MediaUploadX\users\adapter.py", line 22, in send_mail
    msg.send(fail_silently=True)
  File "D:\Programming\MediaUploadX\venv\Lib\site-packages\django\core\mail\message.py", line 298, in send
    return self.get_connection(fail_silently).send_messages([self])
           ^^^^^^^^^^^^^^^^^^^^^^^^^^^^^^^^^^^^^^^^^^^^^^^^^^^^^^^^
  File "D:\Programming\MediaUploadX\venv\Lib\site-packages\djcelery_email\backends.py", line 17, in send_messages
    result_tasks.append(send_emails.delay(chunk_messages, self.init_kwargs))
                        ^^^^^^^^^^^^^^^^^^^^^^^^^^^^^^^^^^^^^^^^^^^^^^^^^^^
  File "D:\Programming\MediaUploadX\venv\Lib\site-packages\celery\app\task.py", line 444, in delay
    return self.apply_async(args, kwargs)
           ^^^^^^^^^^^^^^^^^^^^^^^^^^^^^^
  File "D:\Programming\MediaUploadX\venv\Lib\site-packages\celery\app\task.py", line 594, in apply_async
    return app.send_task(
           ^^^^^^^^^^^^^^
  File "D:\Programming\MediaUploadX\venv\Lib\site-packages\celery\app\base.py", line 798, in send_task
    amqp.send_task_message(P, name, message, **options)
  File "D:\Programming\MediaUploadX\venv\Lib\site-packages\celery\app\amqp.py", line 517, in send_task_message
    ret = producer.publish(
          ^^^^^^^^^^^^^^^^^
  File "D:\Programming\MediaUploadX\venv\Lib\site-packages\kombu\messaging.py", line 186, in publish
    return _publish(
           ^^^^^^^^^
  File "D:\Programming\MediaUploadX\venv\Lib\site-packages\kombu\connection.py", line 563, in _ensured
    return fun(*args, **kwargs)
           ^^^^^^^^^^^^^^^^^^^^
  File "D:\Programming\MediaUploadX\venv\Lib\site-packages\kombu\messaging.py", line 195, in _publish
    channel = self.channel
              ^^^^^^^^^^^^
  File "D:\Programming\MediaUploadX\venv\Lib\site-packages\kombu\messaging.py", line 218, in _get_channel
    channel = self._channel = channel()
                              ^^^^^^^^^
  File "D:\Programming\MediaUploadX\venv\Lib\site-packages\kombu\utils\functional.py", line 34, in __call__
    value = self.__value__ = self.__contract__()
                             ^^^^^^^^^^^^^^^^^^^
  File "D:\Programming\MediaUploadX\venv\Lib\site-packages\kombu\messaging.py", line 234, in <lambda>
    channel = ChannelPromise(lambda: connection.default_channel)
                                     ^^^^^^^^^^^^^^^^^^^^^^^^^^
  File "D:\Programming\MediaUploadX\venv\Lib\site-packages\kombu\connection.py", line 960, in default_channel
    self._ensure_connection(**conn_opts)
  File "D:\Programming\MediaUploadX\venv\Lib\site-packages\kombu\connection.py", line 458, in _ensure_connection
    with ctx():
  File "C:\Python\Lib\contextlib.py", line 155, in __exit__
    self.gen.throw(typ, value, traceback)
  File "D:\Programming\MediaUploadX\venv\Lib\site-packages\kombu\connection.py", line 476, in _reraise_as_library_errors
    raise ConnectionError(str(exc)) from exc
kombu.exceptions.OperationalError: [WinError 10061] No connection could be made because the target machine actively refused it
"POST /accounts/signup/ HTTP/1.1" 500 325890
Internal Server Error: /accounts/signup/
Traceback (most recent call last):
  File "D:\Programming\MediaUploadX\venv\Lib\site-packages\kombu\utils\functional.py", line 32, in __call__
    return self.__value__
           ^^^^^^^^^^^^^^
AttributeError: 'ChannelPromise' object has no attribute '__value__'

During handling of the above exception, another exception occurred:

Traceback (most recent call last):
  File "D:\Programming\MediaUploadX\venv\Lib\site-packages\kombu\connection.py", line 472, in _reraise_as_library_errors
    yield
  File "D:\Programming\MediaUploadX\venv\Lib\site-packages\kombu\connection.py", line 459, in _ensure_connection
    return retry_over_time(
           ^^^^^^^^^^^^^^^^
  File "D:\Programming\MediaUploadX\venv\Lib\site-packages\kombu\utils\functional.py", line 318, in retry_over_time
    return fun(*args, **kwargs)
           ^^^^^^^^^^^^^^^^^^^^
  File "D:\Programming\MediaUploadX\venv\Lib\site-packages\kombu\connection.py", line 941, in _connection_factory
    self._connection = self._establish_connection()
                       ^^^^^^^^^^^^^^^^^^^^^^^^^^^^
  File "D:\Programming\MediaUploadX\venv\Lib\site-packages\kombu\connection.py", line 867, in _establish_connection
    conn = self.transport.establish_connection()
           ^^^^^^^^^^^^^^^^^^^^^^^^^^^^^^^^^^^^^
  File "D:\Programming\MediaUploadX\venv\Lib\site-packages\kombu\transport\pyamqp.py", line 203, in establish_connection
    conn.connect()
  File "D:\Programming\MediaUploadX\venv\Lib\site-packages\amqp\connection.py", line 323, in connect
    self.transport.connect()
  File "D:\Programming\MediaUploadX\venv\Lib\site-packages\amqp\transport.py", line 129, in connect
    self._connect(self.host, self.port, self.connect_timeout)
  File "D:\Programming\MediaUploadX\venv\Lib\site-packages\amqp\transport.py", line 184, in _connect
    self.sock.connect(sa)
ConnectionRefusedError: [WinError 10061] No connection could be made because the target machine actively refused it

The above exception was the direct cause of the following exception:

Traceback (most recent call last):
  File "D:\Programming\MediaUploadX\venv\Lib\site-packages\django\core\handlers\exception.py", line 55, in inner
    response = get_response(request)
               ^^^^^^^^^^^^^^^^^^^^^
  File "D:\Programming\MediaUploadX\venv\Lib\site-packages\django\core\handlers\base.py", line 197, in _get_response
    response = wrapped_callback(request, *callback_args, **callback_kwargs)
               ^^^^^^^^^^^^^^^^^^^^^^^^^^^^^^^^^^^^^^^^^^^^^^^^^^^^^^^^^^^^
  File "D:\Programming\MediaUploadX\venv\Lib\site-packages\django\views\generic\base.py", line 104, in view
    return self.dispatch(request, *args, **kwargs)
           ^^^^^^^^^^^^^^^^^^^^^^^^^^^^^^^^^^^^^^^
  File "D:\Programming\MediaUploadX\venv\Lib\site-packages\django\utils\decorators.py", line 46, in _wrapper
    return bound_method(*args, **kwargs)
           ^^^^^^^^^^^^^^^^^^^^^^^^^^^^^
  File "D:\Programming\MediaUploadX\venv\Lib\site-packages\allauth\decorators.py", line 20, in wrap
    resp = function(request, *args, **kwargs)
           ^^^^^^^^^^^^^^^^^^^^^^^^^^^^^^^^^^
  File "D:\Programming\MediaUploadX\venv\Lib\site-packages\django\utils\decorators.py", line 46, in _wrapper
    return bound_method(*args, **kwargs)
           ^^^^^^^^^^^^^^^^^^^^^^^^^^^^^
  File "D:\Programming\MediaUploadX\venv\Lib\site-packages\django\views\decorators\debug.py", line 92, in sensitive_post_parameters_wrapper
    return view(request, *args, **kwargs)
           ^^^^^^^^^^^^^^^^^^^^^^^^^^^^^^
  File "D:\Programming\MediaUploadX\venv\Lib\site-packages\allauth\account\views.py", line 234, in dispatch
    return super(SignupView, self).dispatch(request, *args, **kwargs)
           ^^^^^^^^^^^^^^^^^^^^^^^^^^^^^^^^^^^^^^^^^^^^^^^^^^^^^^^^^^
  File "D:\Programming\MediaUploadX\venv\Lib\site-packages\allauth\account\views.py", line 77, in dispatch
    response = super(RedirectAuthenticatedUserMixin, self).dispatch(
               ^^^^^^^^^^^^^^^^^^^^^^^^^^^^^^^^^^^^^^^^^^^^^^^^^^^^^
  File "D:\Programming\MediaUploadX\venv\Lib\site-packages\allauth\account\views.py", line 207, in dispatch
    return super(CloseableSignupMixin, self).dispatch(request, *args, **kwargs)
           ^^^^^^^^^^^^^^^^^^^^^^^^^^^^^^^^^^^^^^^^^^^^^^^^^^^^^^^^^^^^^^^^^^^^
  File "D:\Programming\MediaUploadX\venv\Lib\site-packages\django\views\generic\base.py", line 143, in dispatch
    return handler(request, *args, **kwargs)
           ^^^^^^^^^^^^^^^^^^^^^^^^^^^^^^^^^
  File "D:\Programming\MediaUploadX\venv\Lib\site-packages\allauth\account\views.py", line 105, in post
    response = self.form_valid(form)
               ^^^^^^^^^^^^^^^^^^^^^
  File "D:\Programming\MediaUploadX\venv\Lib\site-packages\allauth\account\views.py", line 254, in form_valid
    return complete_signup(
           ^^^^^^^^^^^^^^^^
  File "D:\Programming\MediaUploadX\venv\Lib\site-packages\allauth\account\utils.py", line 186, in complete_signup
    return perform_login(
           ^^^^^^^^^^^^^^
  File "D:\Programming\MediaUploadX\venv\Lib\site-packages\allauth\account\utils.py", line 168, in perform_login
    response = adapter.pre_login(request, user, **hook_kwargs)
               ^^^^^^^^^^^^^^^^^^^^^^^^^^^^^^^^^^^^^^^^^^^^^^^
  File "D:\Programming\MediaUploadX\venv\Lib\site-packages\allauth\account\adapter.py", line 409, in pre_login
    send_email_confirmation(request, user, signup=signup, email=email)
  File "D:\Programming\MediaUploadX\venv\Lib\site-packages\allauth\account\utils.py", line 319, in send_email_confirmation
    email_address.send_confirmation(request, signup=signup)
  File "D:\Programming\MediaUploadX\venv\Lib\site-packages\allauth\account\models.py", line 60, in send_confirmation
    confirmation.send(request, signup=signup)
  File "D:\Programming\MediaUploadX\venv\Lib\site-packages\allauth\account\models.py", line 168, in send
    get_adapter(request).send_confirmation_mail(request, self, signup)
  File "D:\Programming\MediaUploadX\venv\Lib\site-packages\allauth\account\adapter.py", line 549, in send_confirmation_mail
    self.send_mail(email_template, emailconfirmation.email_address.email, ctx)
  File "D:\Programming\MediaUploadX\users\adapter.py", line 22, in send_mail
    msg.send(fail_silently=True)
  File "D:\Programming\MediaUploadX\venv\Lib\site-packages\django\core\mail\message.py", line 298, in send
    return self.get_connection(fail_silently).send_messages([self])
           ^^^^^^^^^^^^^^^^^^^^^^^^^^^^^^^^^^^^^^^^^^^^^^^^^^^^^^^^
  File "D:\Programming\MediaUploadX\venv\Lib\site-packages\djcelery_email\backends.py", line 17, in send_messages
    result_tasks.append(send_emails.delay(chunk_messages, self.init_kwargs))
                        ^^^^^^^^^^^^^^^^^^^^^^^^^^^^^^^^^^^^^^^^^^^^^^^^^^^
  File "D:\Programming\MediaUploadX\venv\Lib\site-packages\celery\app\task.py", line 444, in delay
    return self.apply_async(args, kwargs)
           ^^^^^^^^^^^^^^^^^^^^^^^^^^^^^^
  File "D:\Programming\MediaUploadX\venv\Lib\site-packages\celery\app\task.py", line 594, in apply_async
    return app.send_task(
           ^^^^^^^^^^^^^^
  File "D:\Programming\MediaUploadX\venv\Lib\site-packages\celery\app\base.py", line 798, in send_task
    amqp.send_task_message(P, name, message, **options)
  File "D:\Programming\MediaUploadX\venv\Lib\site-packages\celery\app\amqp.py", line 517, in send_task_message
    ret = producer.publish(
          ^^^^^^^^^^^^^^^^^
  File "D:\Programming\MediaUploadX\venv\Lib\site-packages\kombu\messaging.py", line 186, in publish
    return _publish(
           ^^^^^^^^^
  File "D:\Programming\MediaUploadX\venv\Lib\site-packages\kombu\connection.py", line 563, in _ensured
    return fun(*args, **kwargs)
           ^^^^^^^^^^^^^^^^^^^^
  File "D:\Programming\MediaUploadX\venv\Lib\site-packages\kombu\messaging.py", line 195, in _publish
    channel = self.channel
              ^^^^^^^^^^^^
  File "D:\Programming\MediaUploadX\venv\Lib\site-packages\kombu\messaging.py", line 218, in _get_channel
    channel = self._channel = channel()
                              ^^^^^^^^^
  File "D:\Programming\MediaUploadX\venv\Lib\site-packages\kombu\utils\functional.py", line 34, in __call__
    value = self.__value__ = self.__contract__()
                             ^^^^^^^^^^^^^^^^^^^
  File "D:\Programming\MediaUploadX\venv\Lib\site-packages\kombu\messaging.py", line 234, in <lambda>
    channel = ChannelPromise(lambda: connection.default_channel)
                                     ^^^^^^^^^^^^^^^^^^^^^^^^^^
  File "D:\Programming\MediaUploadX\venv\Lib\site-packages\kombu\connection.py", line 960, in default_channel
    self._ensure_connection(**conn_opts)
  File "D:\Programming\MediaUploadX\venv\Lib\site-packages\kombu\connection.py", line 458, in _ensure_connection
    with ctx():
  File "C:\Python\Lib\contextlib.py", line 155, in __exit__
    self.gen.throw(typ, value, traceback)
  File "D:\Programming\MediaUploadX\venv\Lib\site-packages\kombu\connection.py", line 476, in _reraise_as_library_errors
    raise ConnectionError(str(exc)) from exc
kombu.exceptions.OperationalError: [WinError 10061] No connection could be made because the target machine actively refused it
"POST /accounts/signup/ HTTP/1.1" 500 327563
Internal Server Error: /accounts/signup/
Traceback (most recent call last):
  File "D:\Programming\MediaUploadX\venv\Lib\site-packages\kombu\utils\functional.py", line 32, in __call__
    return self.__value__
           ^^^^^^^^^^^^^^
AttributeError: 'ChannelPromise' object has no attribute '__value__'

During handling of the above exception, another exception occurred:

Traceback (most recent call last):
  File "D:\Programming\MediaUploadX\venv\Lib\site-packages\kombu\connection.py", line 472, in _reraise_as_library_errors
    yield
  File "D:\Programming\MediaUploadX\venv\Lib\site-packages\kombu\connection.py", line 459, in _ensure_connection
    return retry_over_time(
           ^^^^^^^^^^^^^^^^
  File "D:\Programming\MediaUploadX\venv\Lib\site-packages\kombu\utils\functional.py", line 318, in retry_over_time
    return fun(*args, **kwargs)
           ^^^^^^^^^^^^^^^^^^^^
  File "D:\Programming\MediaUploadX\venv\Lib\site-packages\kombu\connection.py", line 941, in _connection_factory
    self._connection = self._establish_connection()
                       ^^^^^^^^^^^^^^^^^^^^^^^^^^^^
  File "D:\Programming\MediaUploadX\venv\Lib\site-packages\kombu\connection.py", line 867, in _establish_connection
    conn = self.transport.establish_connection()
           ^^^^^^^^^^^^^^^^^^^^^^^^^^^^^^^^^^^^^
  File "D:\Programming\MediaUploadX\venv\Lib\site-packages\kombu\transport\pyamqp.py", line 203, in establish_connection
    conn.connect()
  File "D:\Programming\MediaUploadX\venv\Lib\site-packages\amqp\connection.py", line 323, in connect
    self.transport.connect()
  File "D:\Programming\MediaUploadX\venv\Lib\site-packages\amqp\transport.py", line 129, in connect
    self._connect(self.host, self.port, self.connect_timeout)
  File "D:\Programming\MediaUploadX\venv\Lib\site-packages\amqp\transport.py", line 184, in _connect
    self.sock.connect(sa)
ConnectionRefusedError: [WinError 10061] No connection could be made because the target machine actively refused it

The above exception was the direct cause of the following exception:

Traceback (most recent call last):
  File "D:\Programming\MediaUploadX\venv\Lib\site-packages\django\core\handlers\exception.py", line 55, in inner
    response = get_response(request)
               ^^^^^^^^^^^^^^^^^^^^^
  File "D:\Programming\MediaUploadX\venv\Lib\site-packages\django\core\handlers\base.py", line 197, in _get_response
    response = wrapped_callback(request, *callback_args, **callback_kwargs)
               ^^^^^^^^^^^^^^^^^^^^^^^^^^^^^^^^^^^^^^^^^^^^^^^^^^^^^^^^^^^^
  File "D:\Programming\MediaUploadX\venv\Lib\site-packages\django\views\generic\base.py", line 104, in view
    return self.dispatch(request, *args, **kwargs)
           ^^^^^^^^^^^^^^^^^^^^^^^^^^^^^^^^^^^^^^^
  File "D:\Programming\MediaUploadX\venv\Lib\site-packages\django\utils\decorators.py", line 46, in _wrapper
    return bound_method(*args, **kwargs)
           ^^^^^^^^^^^^^^^^^^^^^^^^^^^^^
  File "D:\Programming\MediaUploadX\venv\Lib\site-packages\allauth\decorators.py", line 20, in wrap
    resp = function(request, *args, **kwargs)
           ^^^^^^^^^^^^^^^^^^^^^^^^^^^^^^^^^^
  File "D:\Programming\MediaUploadX\venv\Lib\site-packages\django\utils\decorators.py", line 46, in _wrapper
    return bound_method(*args, **kwargs)
           ^^^^^^^^^^^^^^^^^^^^^^^^^^^^^
  File "D:\Programming\MediaUploadX\venv\Lib\site-packages\django\views\decorators\debug.py", line 92, in sensitive_post_parameters_wrapper
    return view(request, *args, **kwargs)
           ^^^^^^^^^^^^^^^^^^^^^^^^^^^^^^
  File "D:\Programming\MediaUploadX\venv\Lib\site-packages\allauth\account\views.py", line 234, in dispatch
    return super(SignupView, self).dispatch(request, *args, **kwargs)
           ^^^^^^^^^^^^^^^^^^^^^^^^^^^^^^^^^^^^^^^^^^^^^^^^^^^^^^^^^^
  File "D:\Programming\MediaUploadX\venv\Lib\site-packages\allauth\account\views.py", line 77, in dispatch
    response = super(RedirectAuthenticatedUserMixin, self).dispatch(
               ^^^^^^^^^^^^^^^^^^^^^^^^^^^^^^^^^^^^^^^^^^^^^^^^^^^^^
  File "D:\Programming\MediaUploadX\venv\Lib\site-packages\allauth\account\views.py", line 207, in dispatch
    return super(CloseableSignupMixin, self).dispatch(request, *args, **kwargs)
           ^^^^^^^^^^^^^^^^^^^^^^^^^^^^^^^^^^^^^^^^^^^^^^^^^^^^^^^^^^^^^^^^^^^^
  File "D:\Programming\MediaUploadX\venv\Lib\site-packages\django\views\generic\base.py", line 143, in dispatch
    return handler(request, *args, **kwargs)
           ^^^^^^^^^^^^^^^^^^^^^^^^^^^^^^^^^
  File "D:\Programming\MediaUploadX\venv\Lib\site-packages\allauth\account\views.py", line 105, in post
    response = self.form_valid(form)
               ^^^^^^^^^^^^^^^^^^^^^
  File "D:\Programming\MediaUploadX\venv\Lib\site-packages\allauth\account\views.py", line 254, in form_valid
    return complete_signup(
           ^^^^^^^^^^^^^^^^
  File "D:\Programming\MediaUploadX\venv\Lib\site-packages\allauth\account\utils.py", line 186, in complete_signup
    return perform_login(
           ^^^^^^^^^^^^^^
  File "D:\Programming\MediaUploadX\venv\Lib\site-packages\allauth\account\utils.py", line 168, in perform_login
    response = adapter.pre_login(request, user, **hook_kwargs)
               ^^^^^^^^^^^^^^^^^^^^^^^^^^^^^^^^^^^^^^^^^^^^^^^
  File "D:\Programming\MediaUploadX\venv\Lib\site-packages\allauth\account\adapter.py", line 409, in pre_login
    send_email_confirmation(request, user, signup=signup, email=email)
  File "D:\Programming\MediaUploadX\venv\Lib\site-packages\allauth\account\utils.py", line 319, in send_email_confirmation
    email_address.send_confirmation(request, signup=signup)
  File "D:\Programming\MediaUploadX\venv\Lib\site-packages\allauth\account\models.py", line 60, in send_confirmation
    confirmation.send(request, signup=signup)
  File "D:\Programming\MediaUploadX\venv\Lib\site-packages\allauth\account\models.py", line 168, in send
    get_adapter(request).send_confirmation_mail(request, self, signup)
  File "D:\Programming\MediaUploadX\venv\Lib\site-packages\allauth\account\adapter.py", line 549, in send_confirmation_mail
    self.send_mail(email_template, emailconfirmation.email_address.email, ctx)
  File "D:\Programming\MediaUploadX\users\adapter.py", line 22, in send_mail
    msg.send(fail_silently=True)
  File "D:\Programming\MediaUploadX\venv\Lib\site-packages\django\core\mail\message.py", line 298, in send
    return self.get_connection(fail_silently).send_messages([self])
           ^^^^^^^^^^^^^^^^^^^^^^^^^^^^^^^^^^^^^^^^^^^^^^^^^^^^^^^^
  File "D:\Programming\MediaUploadX\venv\Lib\site-packages\djcelery_email\backends.py", line 17, in send_messages
    result_tasks.append(send_emails.delay(chunk_messages, self.init_kwargs))
                        ^^^^^^^^^^^^^^^^^^^^^^^^^^^^^^^^^^^^^^^^^^^^^^^^^^^
  File "D:\Programming\MediaUploadX\venv\Lib\site-packages\celery\app\task.py", line 444, in delay
    return self.apply_async(args, kwargs)
           ^^^^^^^^^^^^^^^^^^^^^^^^^^^^^^
  File "D:\Programming\MediaUploadX\venv\Lib\site-packages\celery\app\task.py", line 594, in apply_async
    return app.send_task(
           ^^^^^^^^^^^^^^
  File "D:\Programming\MediaUploadX\venv\Lib\site-packages\celery\app\base.py", line 798, in send_task
    amqp.send_task_message(P, name, message, **options)
  File "D:\Programming\MediaUploadX\venv\Lib\site-packages\celery\app\amqp.py", line 517, in send_task_message
    ret = producer.publish(
          ^^^^^^^^^^^^^^^^^
  File "D:\Programming\MediaUploadX\venv\Lib\site-packages\kombu\messaging.py", line 186, in publish
    return _publish(
           ^^^^^^^^^
  File "D:\Programming\MediaUploadX\venv\Lib\site-packages\kombu\connection.py", line 563, in _ensured
    return fun(*args, **kwargs)
           ^^^^^^^^^^^^^^^^^^^^
  File "D:\Programming\MediaUploadX\venv\Lib\site-packages\kombu\messaging.py", line 195, in _publish
    channel = self.channel
              ^^^^^^^^^^^^
  File "D:\Programming\MediaUploadX\venv\Lib\site-packages\kombu\messaging.py", line 218, in _get_channel
    channel = self._channel = channel()
                              ^^^^^^^^^
  File "D:\Programming\MediaUploadX\venv\Lib\site-packages\kombu\utils\functional.py", line 34, in __call__
    value = self.__value__ = self.__contract__()
                             ^^^^^^^^^^^^^^^^^^^
  File "D:\Programming\MediaUploadX\venv\Lib\site-packages\kombu\messaging.py", line 234, in <lambda>
    channel = ChannelPromise(lambda: connection.default_channel)
                                     ^^^^^^^^^^^^^^^^^^^^^^^^^^
  File "D:\Programming\MediaUploadX\venv\Lib\site-packages\kombu\connection.py", line 960, in default_channel
    self._ensure_connection(**conn_opts)
  File "D:\Programming\MediaUploadX\venv\Lib\site-packages\kombu\connection.py", line 458, in _ensure_connection
    with ctx():
  File "C:\Python\Lib\contextlib.py", line 155, in __exit__
    self.gen.throw(typ, value, traceback)
  File "D:\Programming\MediaUploadX\venv\Lib\site-packages\kombu\connection.py", line 476, in _reraise_as_library_errors
    raise ConnectionError(str(exc)) from exc
kombu.exceptions.OperationalError: [WinError 10061] No connection could be made because the target machine actively refused it
"POST /accounts/signup/ HTTP/1.1" 500 327757
